Workbook

Sheet ASSEGNAZIONI
A1: DIPENDENTE | B1: CANTIERE | C1: N° CANTIERI
A2: CALDERON GARCES LIUD CLEIDER | B2: CARROZZERIA CHINETTI SRL | C2: =COUNTIF(A:A,A2) -> 11
A3: CALDERON GARCES LIUD CLEIDER | B3: CONDOMINIO BERTANI
A4: CALDERON GARCES LIUD CLEIDER | B4: CONDOMINIO BRUNELLA
A5: CALDERON GARCES LIUD CLEIDER | B5: CONDOMINIO CA' NOVA
A6: CALDERON GARCES LIUD CLEIDER | B6: CONDOMINIO CASA A/1
A7: CALDERON GARCES LIUD CLEIDER | B7: CONDOMINIO CASA B/6
A8: CALDERON GARCES LIUD CLEIDER | B8: CONDOMINIO CASA B7
A9: CALDERON GARCES LIUD CLEIDER | B9: CONDOMINIO VEBE
A10: CALDERON GARCES LIUD CLEIDER | B10: CONDOMINIPO CASA A7
A11: CALDERON GARCES LIUD CLEIDER | B11: RESIDENZA DELLE STELLE
A12: CALDERON GARCES LIUD CLEIDER | B12: SANGALLI FRONT OFFICE
A13: DE CUBELLIS GIUSY | B13: ASSOCIAZIONE DILETTANTISTICA BRIDGE VARESE | C13: =COUNTIF(A:A,A13) -> 6
A14: DE CUBELLIS GIUSY | B14: COMUNE DI CASCIAGO
A15: DE CUBELLIS GIUSY | B15: CONDOMINIO CA' NOVA
A16: DE CUBELLIS GIUSY | B16: EYE CENTER VARESE SRL
A17: DE CUBELLIS GIUSY | B17: PRODOTTI ORCO SRL SOCIETA' ALIMENTARE HELVETIA
A18: DE CUBELLIS GIUSY | B18: SARTORIA VERGALLO SRL
A19: DEMYDASYUK ILONA | B19: AUTORITA' DI BACINO LACUALE CERESIO PIANO E GHIRLA | C19: =COUNTIF(A:A,A19) -> 7
A20: FELTRIN SAMANTHA | B20: BASE BLU UFFICI
A21: DEMYDASYUK ILONA | B21: CONDOMINIO BRUNELLA
A22: DEMYDASYUK ILONA | B22: CONDOMINIO PIEMONTE
A23: DEMYDASYUK ILONA | B23: CONDOMINIO PIEMONTE 1
A24: DEMYDASYUK ILONA | B24: CONDOMINIO SANTA MARIA
A25: DEMYDASYUK ILONA | B25: RESIDENZA SAN QUIRICO - LOTTO B
A26: DESOGOS DOMENICA | B26: AMBULATORI VIGGIU' | C26: =COUNTIF(A:A,A26) -> 15
A27: DESOGOS DOMENICA | B27: AUTOSCUOLA VALCERESIO SRL
A28: DESOGOS DOMENICA | B28: CONDOMINIO GIULIANA/ALESSANDRA
A29: DESOGOS DOMENICA | B29: CONDOMINIO JOLE
A30: DESOGOS DOMENICA | B30: CONDOMINIO PALAZZO BORRI
A31: DESOGOS DOMENICA | B31: CONDOMINIO SANTA MARIA
A32: DESOGOS DOMENICA | B32: DISCARICA SANGALLI
A33: DESOGOS DOMENICA | B33: DOTT. ALFREDO DE NIGRIS
A34: DESOGOS DOMENICA | B34: DOTT. EMANUELE MARITAN
A35: DESOGOS DOMENICA | B35: DOTT. MARCOMARIA CAPPELLO
A36: DESOGOS DOMENICA | B36: DOTT.SSA PAOLA MARIA PATRUNO
A37: DESOGOS DOMENICA | B37: FONDAZIONE ASILO INFANTILE UMBERTO I
A38: DESOGOS DOMENICA | B38: FURIANI SAEL SERVIZI SRL
... A40: DESOGOS DOMENICA | B40: SISCODATA COMPUTER SRL
A41: FELTRIN SAMANTHA | B41: ASSOCIAZIONE CULTURALE IL CERCHIO SCIAMANICO | C41: =COUNTIF(A:A,A41) -> 12
...

Sheet DIPENDENTI
A1: DIPENDENTI BP CLEANING SRL
A2: NOMINATIVO | B2: INDIRIZZO MAIL
A3: REXAJ ELVISA
A4: DEMYDASYUK ILONA
A5: CALDERON GARCES LIUD CLEIDER
A6: GUZHNAY GUAPACASA LUIS CORNELIO
A7: DESOGOS DOMENICA
A8: FELTRIN SAMANTHA
A9: GALIMBERTI UMBERTO
A10: GARGHENTINI DAFNE
A11: SACCON MARCO
A12: SALA MARINA
A13: ZARO VALENTINA
A14: DE CUBELLIS GIUSY
... A17: YASSIM ABDELALIM

Sheet ILONA
A1: CANTIERI
A2: CONDOMINIO PIEMONTE
A3: RESIDENZA SAN QUIRICO - LOTTO B
A4: CONDOMINIO SANTA MARIA
A5: BASE BLU VARANO BORGHI
A6: CONDOMINIO BRUNELLA
A7: AUTORITA' DI BACINO LACUALE CERESIO PIANO E GHIRLA
A8: CONDOMINIO PIEMONTE 1

Sheet ELVISA
A1: CANTIERI
A2: Comune di Arcisate - AREA MANUTENTIVA
A3: IMPRESA SANGALLI GIANCARLO & C. SRL
A4: MECCANICA GIULIANI SRL
A5: FARMACIA NOBILI DI DOTT. L. E G. NOBILI SNC
A6: BASE BLU VARANO BORGHI
A7: BASE BLU UFFICI
A8: NEGOZIO BLU
A9: FONDAZIONE ASILO INFANTILE UMBERTO I
A10: ASSOCIAZIONE CULTURALE IL CERCHIO SCIAMANICO
A11: ALETTI MARIO
A12: AVV. CARLO BATTIPEDE
... A15: CONDOMINIO ARIEL

Sheet MARIA
A1: CANTIERI
A2: CONDOMINIO COSTANZA1
A3: SAVINELLI SRL
A4: CONDOMINIO MALNATI E VANONI
A5: CIVELLI MARGHERITA
A6: CONDOMINIO VIGANA
A7: CONDOMINIO VALGANNA CANOVA
A8: CONDOMINIO VALGANNA CANOVA 16
A9: CONDOMINIO SPES

Sheet LIUD
A1: CANTIERI
A2: CONDOMINIO BRUNELLA
A3: CONDOMINIPO CASA A7
A4: RESIDENZA DELLE STELLE
A5: CONDOMINIO BERTANI
A6: SANGALLI FRONT OFFICE
A7: CONDOMINIO CA' NOVA
A8: CONDOMINIO VEBE
A9: CARROZZERIA CHINETTI SRL
A10: CONDOMINIO CASA A/1
A11: CONDOMINIO CASA B7
A12: CONDOMINIO CASA B/6

Sheet DAFNE
A1: CANTIERI
A2: CONDOMINIO SANTA MARIA
A3: BASE BLU VARANO BORGHI
A4: CONDOMINIO KALIMERA
A5: CONDOMINIO IL CANCELLO
A6: FURIANI SAEL SERVIZI SRL
A7: AMBULATORI VIGGIU'
A8: SISCODATA COMPUTER SRL
A9: CONDOMINIO LAURA
A10: DOTT. EMANUELE MARITAN
A11: DOTT. ALFREDO DE NIGRIS
A12: AVV. CARLO BATTIPEDE
A13: DOTT.SSA PAOLA MARIA PATRUNO

Sheet MARINA
A1: CANTIERI
A2: CONDOMINIO SANTA MARIA
A3: AMBULATORI VIGGIU'
A4: FONDAZIONE ASILO INFANTILE UMBERTO I
A5: CONDOMINIO IL MOLINO
A6: FARMACIE POMI DEI DOTT. ANDREA E ROSELLA POMI & C. s.n.c.
A7: CONDOMINIO IL PORRO
A8: CONDOMINIO PALAZZO BORRI
A9: AUTOSCUOLA VALCERESIO SRL
A10: FARMACIA NOBILI
A11: IMMOBILIARE CONTI SRL

Sheet CORNELIO
A1: CANTIERI
A2: CONDOMINIO COMO
A3: PACO ITALIANA SRL
A4: CASA TIBILETTI
A5: CONDOMINIO SOLE 2
A6: CONDOMINIO SANTA MARIA
A7: SAVINELLI SRL
A8: CONDOMINIO BISBINO
A9: CONDOMINIO ARCHI BASSA

Sheet MARCO
A1: CANTIERI
A2: CONDOMINIO GLI ARCHI
A3: FONDAZIONE ASILO INFANTILE UMBERTO I
A4: MECCANICA GIULIANI SRL
A5: FARMACIA NOBILI DI DOTT. L. E G. NOBILI SNC
A6: IMMOBILIARE CONTI SRL
A7: DOTT. EMANUELE MARITAN
A8: DOTT. ALFREDO DE NIGRIS
A9: AVV. CARLO BATTIPEDE
A10: DOTT.SSA PAOLA MARIA PATRUNO

Sheet UMBERTO
A1: CANTIERI
A2: DOTT. MARCOMARIA CAPPELLO
A3: CONDOMINIO LAURA
A4: CONDOMINIO RESIDENCE GOVI
A5: CONDOMINIO ARCHI BASSA
A6: CONDOMINIO IL POGGIO
A7: CONDOMINIO IL SASSELLO
A8: PRODOTTI ORCO SRL SOCIETA' ALIMENTARE HELVETIA
A9: BASE BLU VARANO BORGHI
A10: CONDOMINIO CRISTINA
A11: EYE CENTER VARESE SRL
A12: AMBULATORI VIGGIU'
... A19: MECCANICA GIULIANI SRL

Sheet ZORKA
A1: CANTIERI
A2: AZIENDA SPECIALE A. PARMIANI

Sheet SAMANTHA
A1: CANTIERI
A2: CONDOMINIO VERATTI 10
A3: RESIDENZA VIA ROBBIONI 1
A4: CONDOMINIO VIA CAMPIGLI
A5: BASE BLU UFFICI
A6: NEGOZIO BLU
A7: STUDIO PONTI PAOLA
A8: RESIDENZA VIA SEMPIONE 4
A9: ASSOCIAZIONE CULTURALE IL CERCHIO SCIAMANICO
A10: CONDOMINIO CAVALLOTTI 3
A11: IMPRESA SANGALLI GIANCARLO & C. SRL
A12: FARMACIE POMI DEI DOTT. ANDREA E ROSELLA POMI & C. s.n.c.
A13: RESIDENZA MASPERO

Sheet DOMENICA
A1: CANTIERI
A2: CONDOMINIO GIULIANA/ALESSANDRA
A3: FONDAZIONE ASILO INFANTILE UMBERTO I
A4: DISCARICA SANGALLI
A5: CONDOMINIO PALAZZO BORRI
A6: CONDOMINIO SANTA MARIA
A7: PALESTRA BRENNO
A8: SISCODATA COMPUTER SRL
A9: FURIANI SAEL SERVIZI SRL
A10: AMBULATORI VIGGIU'
A11: CONDOMINIO JOLE
A12: DOTT. EMANUELE MARITAN
... A16: DOTT.SSA PAOLA MARIA PATRUNO

Sheet VALENTINA
A1: CANTIERI
A2: CONDOMINIO VEBE
A3: CONDOMINIO CARLOTTA
A4: CONDOMINIO CA' NOVA
A5: STUDIO PONTI PAOLA
A6: CONDOMINIO SABOTINO
A7: CONDOMINIO BAGAINI 6
A8: FARMACIE POMI DEI DOTT. ANDREA E ROSELLA POMI & C. s.n.c.
A9: CONDOMINIO DE AMICIS 25
A10: CONDOMINIO PALAZZO BORRI
A11: CONDOMINIO CASE BIANCHE LOTTO C
A12: IMMOBILIARE CONTI SRL
A13: ORDINE PROVINCIALE DEI MEDICI CHIRURGHI E DEGLI ODONTOIATRI

Sheet GIUSY
A1: CANTIERI
A2: CONDOMINIO CA' NOVA
A3: COMUNE DI CASCIAGO
A4: ASSOCIAZIONE DILETTANTISTICA BRIDGE VARESE
A5: EYE CENTER VARESE SRL
A6: SARTORIA VERGALLO SRL
A7: PRODOTTI ORCO SRL SOCIETA' ALIMENTARE HELVETIA

Sheet YASSIM
A1: CANTIERI
A2: IMPRESA SANGALLI GIANCARLO & C. SRL

Sheet RIEPILOGO
A1: RIEPILOGO DIPENDENTI E CANTIERI
A3: STATISTICHE GENERALI
A4: Totale Assegnazioni | B4: =COUNTA(ASSEGNAZIONI!A:A)-1 -> 144
A5: Totale Dipendenti | B5: =COUNTA(DIPENDENTI!A:A)-2 -> 15
A6: Cantieri Unici | B6: {=SUMPRODUCT(1/COUNTIF(ASSEGNAZIONI!B2:B145,ASSEGNAZIONI!B2:B145))} -> 91
A7: Media Cantieri per Dipendente | B7: =ROUND(B4/B5,1) -> 9.6
A9: CANTIERI PER DIPENDENTE | B9: N° CANTIERI
A10: CALDERON GARCES LIUD CLEIDER | B10: =COUNTIF(ASSEGNAZIONI!A:A,A10) -> 11
A11: DE CUBELLIS GIUSY | B11: =COUNTIF(ASSEGNAZIONI!A:A,A11) -> 6
A12: DEMYDASYUK ILONA | B12: =COUNTIF(ASSEGNAZIONI!A:A,A12) -> 7
A13: DESOGOS DOMENICA | B13: =COUNTIF(ASSEGNAZIONI!A:A,A13) -> 15
A14: FELTRIN SAMANTHA | B14: =COUNTIF(ASSEGNAZIONI!A:A,A14) -> 12
A15: GALIMBERTI UMBERTO | B15: =COUNTIF(ASSEGNAZIONI!A:A,A15) -> 18
A16: GARGHENTINI DAFNE | B16: =COUNTIF(ASSEGNAZIONI!A:A,A16) -> 12
A17: GUZHNAY GUAPACASA LUIS CORNELIO | B17: =COUNTIF(ASSEGNAZIONI!A:A,A17) -> 8
A18: KASTRATOVIC ZORKA | B18: =COUNTIF(ASSEGNAZIONI!A:A,A18) -> 1
A19: REXAJ ELVISA | B19: =COUNTIF(ASSEGNAZIONI!A:A,A19) -> 14
A20: RODRIGUEZ HERNANDEZ MARIA ESTHER | B20: =COUNTIF(ASSEGNAZIONI!A:A,A20) -> 8
A21: SACCON MARCO | B21: =COUNTIF(ASSEGNAZIONI!A:A,A21) -> 9
... A24: ZARO VALENTINA | B24: =COUNTIF(ASSEGNAZIONI!A:A,A24) -> 12
A25: TOTALE | B25: =SUM(B10:B24) -> 144
